Workbook
Name ModelStart: 'Inputs'!$C$7
Name CapPrice: 'Inputs'!$C$8
Name PriceEsc: 'Inputs'!$C$9
Name OMEsc: 'Inputs'!$C$10
Name Contingency: 'Inputs'!$C$11
Name Insurance: 'Inputs'!$C$12
Name PropTax: 'Inputs'!$C$13
Name GACost: 'Inputs'!$C$14
Name TaxRate: 'Inputs'!$C$15
Name ITCRate: 'Inputs'!$C$16
Name ITCTransfer: 'Inputs'!$C$17
Name ITCBasisRed: 'Inputs'!$C$18
Name SrRateBase: 'Inputs'!$C$22
Name SrDSCR: 'Inputs'!$C$23
Name SrMaxGear: 'Inputs'!$C$24
Name SrFee: 'Inputs'!$C$25
Name MzRateBase: 'Inputs'!$C$26
Name CombDSCR: 'Inputs'!$C$27
Name TotMaxGear: 'Inputs'!$C$28
Name MzFee: 'Inputs'!$C$29
Name Tenor: 'Inputs'!$C$30
Name CostEquity: 'Inputs'!$C$31
Name TotalCapexInputs: 'Inputs'!$T$40
Name MACRS_5: 'Inputs'!$C$45:$C$60
Name MACRS_15: 'Inputs'!$D$45:$D$60
Name ScenarioSel: 'Scenarios'!$C$5
Name CapexAdj: 'Scenarios'!$H$9
Name PriceAdj: 'Scenarios'!$H$10
Name Delay: 'Scenarios'!$H$11
Name RateAdj: 'Scenarios'!$H$12
Name OMAdj: 'Scenarios'!$H$13
Name TotalCapex: 'Annual'!$C$20
Name ConvYear: 'Annual'!$C$30
Name SrRate: 'Annual'!$C$31
Name MzRate: 'Annual'!$C$32
Name SrAmt: 'Annual'!$C$43
Name MzAmt: 'Annual'!$C$56
Name EqIRR: 'Summary'!$C$8
Name CostEquityOut: 'Summary'!$C$9
Name ProjIRR: 'Summary'!$C$10
Name WACC: 'Summary'!$C$11
Name ProjNPV: 'Summary'!$C$12
Name EqNPV: 'Summary'!$C$13
Name Payback: 'Summary'!$C$14
Name MinDSCRSr: 'Summary'!$C$23
Name AvgDSCRSr: 'Summary'!$C$24
Name MinDSCRComb: 'Summary'!$C$25
Name Gearing: 'Summary'!$C$26
Name ConvYearOut: 'Summary'!$C$27
Name RequiredPrice: 'Scenarios'!$O$10

Sheet Cover
B2: Battery Storage Project Finance & Capacity Pricing Model
B3: Portfolio of front-of-the-meter battery storage and backup generation assets · Kshama Upadhyay
B5: Purpose | C5: Value a 400 MW portfolio (four BESS sites + one backup generation site), size a senior/mezzanine/equity capital stack, and solve for the capacity price that delivers the sponsor's target equity IRR.
B6: Status | C6: All assumptions are illustrative and logged in 'Assumption Log' with an owner and a validation source. Not investment advice.
B7: Units | C7: Nominal USD, $ thousands ($k) unless stated. Monthly operating timeline Jan-2027 to Dec-2049; financing and returns annual.
B9: Sheet guide
B10: Summary | C10: Returns, capital stack, required capacity price, debt metrics, charts.
B11: Inputs | C11: General, market, tax and financing assumptions, asset-level table, MACRS tables.
B12: Scenarios | C12: Active-case selector (Base / Downside / Upside), sensitivity flex cells, Excel Data Tables, required-price solver.
B13: Monthly | C13: Asset-level operating flags, degradation, revenue, opex and construction capex by month.
B14: Annual | C14: Annual roll-up, ITC, MACRS depreciation, sculpted senior and mezz debt, tax, project and equity cash flows.
B15: Assumption Log | C15: Every input with owner, basis and validation source; values link live to Inputs.
B16: Checks | C16: Integrity checks (debt repaid, DSCR floors, sources = uses, monthly-to-annual tie-outs).
B18: Conventions | C18: Blue on yellow = hard-coded input · black = formula · green = link to another sheet. No hard-codes in calculation sheets.
B19: Methodology | C19: Debt is sized at term conversion (latest COD) by sculpting debt service to CFADS / target DSCR, capped by gearing. Mezzanine takes the gap between the senior and combined DSCR targets. CFADS for sizing is pre-tax EBITDA (no circularity). Storage ITC is monetized by transfer the year after COD. Tax losses are assumed usable by the sponsor.
B20: How to re-solve price | C20: Scenarios!O10 updates automatically on recalc. Or use Data → What-If Analysis → Goal Seek: set Summary!C8 (Equity IRR) to the target by changing Inputs!CapPrice.
B21: Recalculation | C21: If Data Tables look stale, press F9 (or set Formulas → Calculation Options → Automatic).

Sheet Summary
B2: Battery Storage Portfolio — Project Finance Summary
B3: Front-of-the-meter storage + backup generation. Live outputs for the active scenario. $k unless stated.
B5: Active scenario | C5: =Scenarios!D5 | E5: Model checks | F5: =IF(Checks!C4,"ALL OK","CHECK ERRORS")
B7: Returns & valuation | E7: Sources & uses at term conversion
B8: Equity IRR (levered, after-tax) | C8: =IRR(Annual!$E$75:$AA$75) | F8: $k | G8: % total
B9: Target equity IRR | C9: =CostEquity | E9: Senior debt | F9: =SrAmt | G9: =F9/$F$12
B10: Project IRR (unlevered, after-tax) | C10: =IRR(Annual!$E$74:$AA$74) | E10: Mezzanine debt | F10: =MzAmt | G10: =F10/$F$12
B11: WACC (discount rate for project NPV) | C11: =(SrAmt*SrRate*(1-TaxRate)+MzAmt*MzRate*(1-TaxRate)+(TotalCapex-SrAmt-MzAmt)*CostEquity)/TotalCapex | E11: Sponsor equity | F11: =TotalCapex-SrAmt-MzAmt | G11: =F11/$F$12
B12: Project NPV @ WACC | C12: =NPV(WACC,Annual!$E$74:$AA$74) | E12: Total sources | F12: =SUM(F9:F11) | G12: =SUM(G9:G11)
B13: Equity NPV @ cost of equity | C13: =NPV(CostEquity,Annual!$E$75:$AA$75) | E13: Total capex (uses) | F13: =TotalCapex
B14: Equity payback year (cumulative ≥ 0) | C14: =IFERROR(INDEX(Annual!$E$5:$AA$5,MATCH(TRUE,INDEX(Annual!$E$76:$AA$76>=0,0),0)),"n/a") | E14: ITC cash (transfer, post-COD) | F14: =Annual!D21
E15: Upfront financing fees (equity-funded) | F15: =Annual!D64
B16: Capacity pricing
B17: Capacity price in live case ($/kW-month, 2027 $) | C17: =CapPrice*(1+PriceAdj) | E17: Portfolio
B18: Required price for target equity IRR | C18: =RequiredPrice | E18: Asset | F18: MW | G18: MWh | H18: Capex $k | I18: Live COD
B19: Headroom vs. required price | C19: =IFERROR(C17/C18-1,"n/a") | E19: =Inputs!B35&" ("&Inputs!C35&")" | F19: =Inputs!D35 | G19: =Inputs!S35 | H19: =Inputs!T35 | I19: =Inputs!U35
B20: Required price is interpolated from the Scenarios solver table; Goal Seek EqIRR → CostEquity by changing Inputs!CapPrice gives the same answer. | E20: =Inputs!B36&" ("&Inputs!C36&")" | F20: =Inputs!D36 | G20: =Inputs!S36 | H20: =Inputs!T36 | I20: =Inputs!U36
E21: =Inputs!B37&" ("&Inputs!C37&")" | F21: =Inputs!D37 | G21: =Inputs!S37 | H21: =Inputs!T37 | I21: =Inputs!U37
B22: Debt metrics | E22: =Inputs!B38&" ("&Inputs!C38&")" | F22: =Inputs!D38 | G22: =Inputs!S38 | H22: =Inputs!T38 | I22: =Inputs!U38
B23: Minimum senior DSCR | C23: =MIN(Annual!$E$65:$AA$65) | E23: =Inputs!B39&" ("&Inputs!C39&")" | F23: =Inputs!D39 | G23: =Inputs!S39 | H23: =Inputs!T39 | I23: =Inputs!U39
B24: Average senior DSCR | C24: =AVERAGE(Annual!$E$65:$AA$65) | E24: Total | F24: =SUM(F19:F23) | G24: =SUM(G19:G23) | H24: =SUM(H19:H23)
B25: Minimum combined DSCR | C25: =MIN(Annual!$E$66:$AA$66)
B26: Total gearing (debt / capex) | C26: =(SrAmt+MzAmt)/TotalCapex
B27: Term conversion year | C27: =ConvYear

Sheet Inputs
B2: Inputs
B3: Blue cells on yellow are inputs. Black cells are formulas. $ figures in thousands ($k) unless stated.
B5: General & market
B6: Assumption | C6: Value | D6: Unit | E6: Note
B7: Model start / valuation date | C7: 46388 | D7: date | E7: Monthly timeline starts here; NPVs are discounted to this date
B8: Capacity price (2027 $) | C8: 11 | D8: $/kW-month | E8: Paid on accredited MW. Use Goal Seek or Scenarios!required price to back-solve
B9: Capacity price & margin escalation | C9: 0.02 | D9: % / yr
B10: O&M, lease & G&A escalation | C10: 0.025 | D10: % / yr
B11: Owner's costs & contingency | C11: 0.05 | D11: % of EPC | E11: Applied on top of EPC unit costs
B12: Insurance | C12: 0.004 | D12: % capex / yr
B13: Property tax | C13: 0.005 | D13: % capex / yr
B14: Portfolio G&A and asset management | C14: 1000 | D14: $k / yr | E14: Starts at first COD, escalates with O&M
B15: Blended income tax rate | C15: 0.26 | D15: % | E15: Losses assumed usable by sponsor (negative tax = benefit)
B16: Investment tax credit (storage only) | C16: 0.3 | D16: % eligible capex | E16: Monetized via transfer; cash received the year after COD
B17: ITC transfer price | C17: 0.92 | D17: $ per $1 credit
B18: Depreciable basis reduction | C18: 0.5 | D18: % of ITC
B20: Financing
B21: Assumption | C21: Value | D21: Unit | E21: Note
B22: Senior debt interest rate | C22: 0.065 | D22: % / yr | E22: Live rate adds Scenarios rate adjustment
B23: Senior target DSCR | C23: 1.35 | D23: x | E23: Debt service sculpted to CFADS / target DSCR
B24: Senior max gearing | C24: 0.6 | D24: % of capex | E24: Cap on senior sizing
B25: Senior upfront fee | C25: 0.015 | D25: % of amount
B26: Mezzanine interest rate | C26: 0.105 | D26: % / yr
B27: Combined (senior + mezz) target DSCR | C27: 1.2 | D27: x | E27: Mezz takes the gap between senior and combined DSCR
B28: Total max gearing | C28: 0.75 | D28: % of capex
B29: Mezzanine upfront fee | C29: 0.02 | D29: % of amount
B30: Debt tenor (both tranches) | C30: 15 | D30: years | E30: From term conversion (latest COD)
B31: Cost of equity / target equity IRR | C31: 0.11 | D31: % | E31: Hurdle for required capacity price
B33: Asset portfolio | R33: Calculated (do not edit) →
B34: Asset | C34: Technology | D34: MW | E34: Duration (h) | F34: EPC unit cost | G34: Cost unit | H34: Build (months) | I34: COD (base) | J34: Capacity accreditation | K34: Degradation / yr | L34: Fixed O&M $/kW-yr | M34: Energy & ancillary margin $/kW-yr | N34: Site lease $k/yr | O34: ITC eligible (1/0) | P34: MACRS life (5/15) | Q34: Useful life (yrs) | R34: $/kW (EPC) | S34: MWh | T34: Total capex $k | U34: COD (live, incl. delay) | V34: COD year | W34: Capex start | X34: ITC $k | Y34: Tax basis $k | Z34: Life end
B35: Alpha | C35: BESS | D35: 100 | E35: 4 | F35: 330 | G35: $/kWh | H35: 11 | I35: 46722 | J35: 0.9 | K35: 0.02 | L35: 28 | M35: 45 | N35: 150 | O35: 1 | P35: 5 | Q35: 20 | R35: =F35*IF(G35="$/kWh",E35,1) | S35: =D35*E35 | T35: =D35*R35*(1+Contingency)*(1+CapexAdj) | U35: =EDATE(I35,Delay) | V35: =YEAR(U35) | W35: =EDATE(I35,-H35) | X35: =T35*ITCRate*O35 | Y35: =T35*(1-ITCBasisRed*ITCRate*O35) | Z35: =EDATE(U35,12*Q35)
B36: Bravo | C36: BESS | D36: 75 | E36: 4 | F36: 335 | G36: $/kWh | H36: 12 | I36: 46753 | J36: 0.9 | K36: 0.02 | L36: 28 | M36: 45 | N36: 120 | O36: 1 | P36: 5 | Q36: 20 | R36: =F36*IF(G36="$/kWh",E36,1) | S36: =D36*E36 | T36: =D36*R36*(1+Contingency)*(1+CapexAdj) | U36: =EDATE(I36,Delay) | V36: =YEAR(U36) | W36: =EDATE(I36,-H36) | X36: =T36*ITCRate*O36 | Y36: =T36*(1-ITCBasisRed*ITCRate*O36) | Z36: =EDATE(U36,12*Q36)
B37: Charlie | C37: BESS | D37: 50 | E37: 2 | F37: 390 | G37: $/kWh | H37: 9 | I37: 46844 | J37: 0.6 | K37: 0.025 | L37: 24 | M37: 35 | N37: 90 | O37: 1 | P37: 5 | Q37: 20 | R37: =F37*IF(G37="$/kWh",E37,1) | S37: =D37*E37 | T37: =D37*R37*(1+Contingency)*(1+CapexAdj) | U37: =EDATE(I37,Delay) | V37: =YEAR(U37) | W37: =EDATE(I37,-H37) | X37: =T37*ITCRate*O37 | Y37: =T37*(1-ITCBasisRed*ITCRate*O37) | Z37: =EDATE(U37,12*Q37)
B38: Delta | C38: BESS | D38: 125 | E38: 4 | F38: 325 | G38: $/kWh | H38: 14 | I38: 46935 | J38: 0.9 | K38: 0.02 | L38: 27 | M38: 45 | N38: 180 | O38: 1 | P38: 5 | Q38: 20 | R38: =F38*IF(G38="$/kWh",E38,1) | S38: =D38*E38 | T38: =D38*R38*(1+Contingency)*(1+CapexAdj) | U38: =EDATE(I38,Delay) | V38: =YEAR(U38) | W38: =EDATE(I38,-H38) | X38: =T38*ITCRate*O38 | Y38: =T38*(1-ITCBasisRed*ITCRate*O38) | Z38: =EDATE(U38,12*Q38)
B39: Echo | C39: Backup gen | D39: 50 | E39: 0 | F39: 1350 | G39: $/kW | H39: 15 | I39: 46935 | J39: 0.95 | K39: 0 | L39: 22 | M39: 10 | N39: 80 | O39: 0 | P39: 15 | Q39: 20 | R39: =F39*IF(G39="$/kWh",E39,1) | S39: =D39*E39 | T39: =D39*R39*(1+Contingency)*(1+CapexAdj) | U39: =EDATE(I39,Delay) | V39: =YEAR(U39) | W39: =EDATE(I39,-H39) | X39: =T39*ITCRate*O39 | Y39: =T39*(1-ITCBasisRed*ITCRate*O39) | Z39: =EDATE(U39,12*Q39)
B40: Portfolio | D40: =SUM(D35:D39) | S40: =SUM(S35:S39) | T40: =SUM(T35:T39) | X40: =SUM(X35:X39) | Y40: =SUM(Y35:Y39)
B41: EPC unit cost is $/kWh for storage (× duration) and $/kW for generation.
B43: MACRS depreciation (half-year convention)
B44: Tax year | C44: 5-year | D44: 15-year
B45: 1 | C45: 0.2 | D45: 0.05
...

Sheet Scenarios
B2: Scenarios & Sensitivities
B3: Pick the live case in C5. Sensitivity flex (column G) layers on top of the scenario. Tables below are Excel Data Tables (What-If) and refresh on recalc (F9).
B5: Active scenario (1 Base, 2 Downside, 3 Upside) | C5: 1 | D5: =INDEX(C8:E8,C5) | J5: Required capacity price solver
J6: Equity IRR across capacity-price flex (Data Table on G10); price where IRR crosses the target is interpolated.
B7: Driver | F7: Active scenario | G7: Sensitivity flex | H7: Live value | J7: Price flex | K7: Equity IRR | L7: Price $/kW-mo | N7: Solver output
B8: Scenario name | C8: Base | D8: Downside | E8: Upside | J8: Live case → | K8: =IFERROR(EqIRR,-1) | N8: First row ≥ target | O8: =IFERROR(MATCH(TRUE,INDEX($K$9:$K$49>=CostEquity,0),0),0)
B9: Capex adjustment | C9: 0 | D9: 0.1 | E9: -0.05 | F9: =CHOOSE(ScenarioSel,C9,D9,E9) | G9: 0 | H9: =F9+G9 | J9: -0.4 | L9: =CapPrice*(1+$F$10+J9) | N9: Required price flex | O9: =IF(OR(O8<=1),NA(),INDEX($J$9:$J$49,O8-1)+(CostEquity-INDEX($K$9:$K$49,O8-1))*(INDEX($J$9:$J$49,O8)-INDEX($J$9:$J$49,O8-1))/(INDEX($K$9:$K$49,O8)-INDEX($K$9:$K$49,O8-1)))
B10: Capacity price adjustment | C10: 0 | D10: -0.1 | E10: 0.05 | F10: =CHOOSE(ScenarioSel,C10,D10,E10) | G10: 0 | H10: =F10+G10 | J10: -0.38 | L10: =CapPrice*(1+$F$10+J10) | N10: Required capacity price | O10: =IFERROR(CapPrice*(1+$F$10+O9),"outside ±40%")
B11: COD delay (months) | C11: 0 | D11: 6 | E11: 0 | F11: =CHOOSE(ScenarioSel,C11,D11,E11) | G11: 0 | H11: =F11+G11 | J11: -0.36 | L11: =CapPrice*(1+$F$10+J11)
B12: Interest rate adjustment (bps) | C12: 0 | D12: 100 | E12: -50 | F12: =CHOOSE(ScenarioSel,C12,D12,E12) | G12: 0 | H12: =F12+G12 | J12: -0.34 | L12: =CapPrice*(1+$F$10+J12)
B13: Fixed O&M adjustment | C13: 0 | D13: 0.1 | E13: -0.05 | F13: =CHOOSE(ScenarioSel,C13,D13,E13) | G13: 0 | H13: =F13+G13 | J13: -0.32 | L13: =CapPrice*(1+$F$10+J13)
B14: Delay pushes every COD (and term conversion) back; construction spend timing is unchanged. | J14: -0.3 | L14: =CapPrice*(1+$F$10+J14)
J15: -0.28 | L15: =CapPrice*(1+$F$10+J15)
B16: Scenario comparison (varies C5: 1 Base · 2 Downside · 3 Upside) | J16: -0.26 | L16: =CapPrice*(1+$F$10+J16)
B17: Input ↓ / output → | C17: Equity IRR | D17: Project IRR | E17: Project NPV | F17: Equity NPV | G17: Min senior DSCR | H17: Total debt | J17: -0.24 | L17: =CapPrice*(1+$F$10+J17)
B18: Live case → | C18: =EqIRR | D18: =ProjIRR | E18: =ProjNPV | F18: =EqNPV | G18: =MinDSCRSr | H18: =SrAmt+MzAmt | J18: -0.22 | L18: =CapPrice*(1+$F$10+J18)
B19: 1 | J19: -0.2 | L19: =CapPrice*(1+$F$10+J19)
B20: 2 | J20: -0.18 | L20: =CapPrice*(1+$F$10+J20)
B21: 3 | J21: -0.16 | L21: =CapPrice*(1+$F$10+J21)
J22: -0.14 | L22: =CapPrice*(1+$F$10+J22)
B23: Capex sensitivity (flex on G9) | J23: -0.12 | L23: =CapPrice*(1+$F$10+J23)
B24: Input ↓ / output → | C24: Equity IRR | D24: Project IRR | E24: Project NPV | F24: Equity NPV | G24: Min senior DSCR | H24: Total debt | J24: -0.1 | L24: =CapPrice*(1+$F$10+J24)
B25: Live case → | C25: =EqIRR | D25: =ProjIRR | E25: =ProjNPV | F25: =EqNPV | G25: =MinDSCRSr | H25: =SrAmt+MzAmt | J25: -0.08 | L25: =CapPrice*(1+$F$10+J25)
B26: -0.2 | J26: -0.06 | L26: =CapPrice*(1+$F$10+J26)
B27: -0.1 | J27: -0.04 | L27: =CapPrice*(1+$F$10+J27)
B28: -0.05 | J28: -0.02 | L28: =CapPrice*(1+$F$10+J28)
B29: 0 | J29: 0 | L29: =CapPrice*(1+$F$10+J29)
B30: 0.05 | J30: 0.02 | L30: =CapPrice*(1+$F$10+J30)
B31: 0.1 | J31: 0.04 | L31: =CapPrice*(1+$F$10+J31)
B32: 0.2 | J32: 0.06 | L32: =CapPrice*(1+$F$10+J32)
J33: 0.08 | L33: =CapPrice*(1+$F$10+J33)
B34: Capacity price sensitivity (flex on G10) | J34: 0.1 | L34: =CapPrice*(1+$F$10+J34)
B35: Input ↓ / output → | C35: Equity IRR | D35: Project IRR | E35: Project NPV | F35: Equity NPV | G35: Min senior DSCR | H35: Total debt | J35: 0.12 | L35: =CapPrice*(1+$F$10+J35)
B36: Live case → | C36: =EqIRR | D36: =ProjIRR | E36: =ProjNPV | F36: =EqNPV | G36: =MinDSCRSr | H36: =SrAmt+MzAmt | J36: 0.14 | L36: =CapPrice*(1+$F$10+J36)
B37: -0.2 | J37: 0.16 | L37: =CapPrice*(1+$F$10+J37)
B38: -0.1 | J38: 0.18 | L38: =CapPrice*(1+$F$10+J38)
B39: -0.05 | J39: 0.2 | L39: =CapPrice*(1+$F$10+J39)
B40: 0 | J40: 0.22 | L40: =CapPrice*(1+$F$10+J40)
B41: 0.05 | J41: 0.24 | L41: =CapPrice*(1+$F$10+J41)
B42: 0.1 | J42: 0.26 | L42: =CapPrice*(1+$F$10+J42)
...

Sheet Monthly
B2: Monthly operating cash flows
B3: Asset-level operations and capex by month, $k. Timeline columns are formulas off Inputs!ModelStart.
B5: Month starting | D5: Total | E5: =ModelStart | F5: =EDATE(E5,1) | G5: =EDATE(F5,1) | H5: =EDATE(G5,1) | I5: =EDATE(H5,1) | J5: =EDATE(I5,1) | K5: =EDATE(J5,1) | L5: =EDATE(K5,1) | M5: =EDATE(L5,1) | ... JT5: =EDATE(JS5,1)
B6: Year | E6: =YEAR(E5) | F6: =YEAR(F5) | G6: =YEAR(G5) | H6: =YEAR(H5) | I6: =YEAR(I5) | J6: =YEAR(J5) | K6: =YEAR(K5) | L6: =YEAR(L5) | ... JT6: =YEAR(JT5)
B7: Years from model start | E7: =E6-YEAR(ModelStart) | F7: =F6-YEAR(ModelStart) | G7: =G6-YEAR(ModelStart) | H7: =H6-YEAR(ModelStart) | I7: =I6-YEAR(ModelStart) | J7: =J6-YEAR(ModelStart) | K7: =K6-YEAR(ModelStart) | L7: =L6-YEAR(ModelStart) | ... JT7: =JT6-YEAR(ModelStart)
B8: Capacity price (live) | C8: $/kW-mo | E8: =CapPrice*(1+PriceAdj)*(1+PriceEsc)^E7 | F8: =CapPrice*(1+PriceAdj)*(1+PriceEsc)^F7 | G8: =CapPrice*(1+PriceAdj)*(1+PriceEsc)^G7 | H8: =CapPrice*(1+PriceAdj)*(1+PriceEsc)^H7 | I8: =CapPrice*(1+PriceAdj)*(1+PriceEsc)^I7 | J8: =CapPrice*(1+PriceAdj)*(1+PriceEsc)^J7 | K8: =CapPrice*(1+PriceAdj)*(1+PriceEsc)^K7 | L8: =CapPrice*(1+PriceAdj)*(1+PriceEsc)^L7 | ... JT8: =CapPrice*(1+PriceAdj)*(1+PriceEsc)^JT7
B9: Price escalation index | C9: x | E9: =(1+PriceEsc)^E7 | F9: =(1+PriceEsc)^F7 | G9: =(1+PriceEsc)^G7 | H9: =(1+PriceEsc)^H7 | I9: =(1+PriceEsc)^I7 | J9: =(1+PriceEsc)^J7 | K9: =(1+PriceEsc)^K7 | L9: =(1+PriceEsc)^L7 | ... JT9: =(1+PriceEsc)^JT7
B10: O&M escalation index | C10: x | E10: =(1+OMEsc)^E7 | F10: =(1+OMEsc)^F7 | G10: =(1+OMEsc)^G7 | H10: =(1+OMEsc)^H7 | I10: =(1+OMEsc)^I7 | J10: =(1+OMEsc)^J7 | K10: =(1+OMEsc)^K7 | L10: =(1+OMEsc)^L7 | ... JT10: =(1+OMEsc)^JT7
B12: Alpha — BESS 100 MW / 400 MWh
B13: Operating flag | C13: 1/0 | E13: =IF(AND(E$5>=Inputs!$U$35,E$5<Inputs!$Z$35),1,0) | F13: =IF(AND(F$5>=Inputs!$U$35,F$5<Inputs!$Z$35),1,0) | G13: =IF(AND(G$5>=Inputs!$U$35,G$5<Inputs!$Z$35),1,0) | H13: =IF(AND(H$5>=Inputs!$U$35,H$5<Inputs!$Z$35),1,0) | I13: =IF(AND(I$5>=Inputs!$U$35,I$5<Inputs!$Z$35),1,0) | J13: =IF(AND(J$5>=Inputs!$U$35,J$5<Inputs!$Z$35),1,0) | K13: =IF(AND(K$5>=Inputs!$U$35,K$5<Inputs!$Z$35),1,0) | L13: =IF(AND(L$5>=Inputs!$U$35,L$5<Inputs!$Z$35),1,0) | ... JT13: =IF(AND(JT$5>=Inputs!$U$35,JT$5<Inputs!$Z$35),1,0)
B14: Operating year | C14: # | E14: =IF(E13=1,INT(((YEAR(E$5)-YEAR(Inputs!$U$35))*12+MONTH(E$5)-MONTH(Inputs!$U$35))/12),0) | F14: =IF(F13=1,INT(((YEAR(F$5)-YEAR(Inputs!$U$35))*12+MONTH(F$5)-MONTH(Inputs!$U$35))/12),0) | G14: =IF(G13=1,INT(((YEAR(G$5)-YEAR(Inputs!$U$35))*12+MONTH(G$5)-MONTH(Inputs!$U$35))/12),0) | H14: =IF(H13=1,INT(((YEAR(H$5)-YEAR(Inputs!$U$35))*12+MONTH(H$5)-MONTH(Inputs!$U$35))/12),0) | I14: =IF(I13=1,INT(((YEAR(I$5)-YEAR(Inputs!$U$35))*12+MONTH(I$5)-MONTH(Inputs!$U$35))/12),0) | J14: =IF(J13=1,INT(((YEAR(J$5)-YEAR(Inputs!$U$35))*12+MONTH(J$5)-MONTH(Inputs!$U$35))/12),0) | K14: =IF(K13=1,INT(((YEAR(K$5)-YEAR(Inputs!$U$35))*12+MONTH(K$5)-MONTH(Inputs!$U$35))/12),0) | L14: =IF(L13=1,INT(((YEAR(L$5)-YEAR(Inputs!$U$35))*12+MONTH(L$5)-MONTH(Inputs!$U$35))/12),0) | ... JT14: =IF(JT13=1,INT(((YEAR(JT$5)-YEAR(Inputs!$U$35))*12+MONTH(JT$5)-MONTH(Inputs!$U$35))/12),0)
B15: Accredited capacity (after degradation) | C15: MW | E15: =E13*Inputs!$D$35*Inputs!$J$35*(1-Inputs!$K$35)^E14 | F15: =F13*Inputs!$D$35*Inputs!$J$35*(1-Inputs!$K$35)^F14 | G15: =G13*Inputs!$D$35*Inputs!$J$35*(1-Inputs!$K$35)^G14 | H15: =H13*Inputs!$D$35*Inputs!$J$35*(1-Inputs!$K$35)^H14 | I15: =I13*Inputs!$D$35*Inputs!$J$35*(1-Inputs!$K$35)^I14 | J15: =J13*Inputs!$D$35*Inputs!$J$35*(1-Inputs!$K$35)^J14 | K15: =K13*Inputs!$D$35*Inputs!$J$35*(1-Inputs!$K$35)^K14 | L15: =L13*Inputs!$D$35*Inputs!$J$35*(1-Inputs!$K$35)^L14 | ... JT15: =JT13*Inputs!$D$35*Inputs!$J$35*(1-Inputs!$K$35)^JT14
B16: Capacity revenue | C16: $k | D16: =SUM(E16:JT16) | E16: =E15*E$8 | F16: =F15*F$8 | G16: =G15*G$8 | H16: =H15*H$8 | I16: =I15*I$8 | J16: =J15*J$8 | K16: =K15*K$8 | L16: =L15*L$8 | ... JT16: =JT15*JT$8
B17: Energy & ancillary margin | C17: $k | D17: =SUM(E17:JT17) | E17: =E15*Inputs!$M$35/12*E$9 | F17: =F15*Inputs!$M$35/12*F$9 | G17: =G15*Inputs!$M$35/12*G$9 | H17: =H15*Inputs!$M$35/12*H$9 | I17: =I15*Inputs!$M$35/12*I$9 | J17: =J15*Inputs!$M$35/12*J$9 | K17: =K15*Inputs!$M$35/12*K$9 | L17: =L15*Inputs!$M$35/12*L$9 | ... JT17: =JT15*Inputs!$M$35/12*JT$9
B18: Fixed O&M | C18: $k | D18: =SUM(E18:JT18) | E18: =E13*Inputs!$D$35*Inputs!$L$35/12*E$10*(1+OMAdj) | F18: =F13*Inputs!$D$35*Inputs!$L$35/12*F$10*(1+OMAdj) | G18: =G13*Inputs!$D$35*Inputs!$L$35/12*G$10*(1+OMAdj) | H18: =H13*Inputs!$D$35*Inputs!$L$35/12*H$10*(1+OMAdj) | I18: =I13*Inputs!$D$35*Inputs!$L$35/12*I$10*(1+OMAdj) | J18: =J13*Inputs!$D$35*Inputs!$L$35/12*J$10*(1+OMAdj) | K18: =K13*Inputs!$D$35*Inputs!$L$35/12*K$10*(1+OMAdj) | L18: =L13*Inputs!$D$35*Inputs!$L$35/12*L$10*(1+OMAdj) | ... JT18: =JT13*Inputs!$D$35*Inputs!$L$35/12*JT$10*(1+OMAdj)
B19: Insurance & property tax | C19: $k | D19: =SUM(E19:JT19) | E19: =E13*Inputs!$T$35*(Insurance+PropTax)/12 | F19: =F13*Inputs!$T$35*(Insurance+PropTax)/12 | G19: =G13*Inputs!$T$35*(Insurance+PropTax)/12 | H19: =H13*Inputs!$T$35*(Insurance+PropTax)/12 | I19: =I13*Inputs!$T$35*(Insurance+PropTax)/12 | J19: =J13*Inputs!$T$35*(Insurance+PropTax)/12 | K19: =K13*Inputs!$T$35*(Insurance+PropTax)/12 | L19: =L13*Inputs!$T$35*(Insurance+PropTax)/12 | ... JT19: =JT13*Inputs!$T$35*(Insurance+PropTax)/12
B20: Site lease | C20: $k | D20: =SUM(E20:JT20) | E20: =E13*Inputs!$N$35/12*E$10 | F20: =F13*Inputs!$N$35/12*F$10 | G20: =G13*Inputs!$N$35/12*G$10 | H20: =H13*Inputs!$N$35/12*H$10 | I20: =I13*Inputs!$N$35/12*I$10 | J20: =J13*Inputs!$N$35/12*J$10 | K20: =K13*Inputs!$N$35/12*K$10 | L20: =L13*Inputs!$N$35/12*L$10 | ... JT20: =JT13*Inputs!$N$35/12*JT$10
B21: Construction capex | C21: $k | D21: =SUM(E21:JT21) | E21: =IF(AND(E$5>=Inputs!$W$35,E$5<Inputs!$I$35),Inputs!$T$35/Inputs!$H$35,0) | F21: =IF(AND(F$5>=Inputs!$W$35,F$5<Inputs!$I$35),Inputs!$T$35/Inputs!$H$35,0) | G21: =IF(AND(G$5>=Inputs!$W$35,G$5<Inputs!$I$35),Inputs!$T$35/Inputs!$H$35,0) | H21: =IF(AND(H$5>=Inputs!$W$35,H$5<Inputs!$I$35),Inputs!$T$35/Inputs!$H$35,0) | I21: =IF(AND(I$5>=Inputs!$W$35,I$5<Inputs!$I$35),Inputs!$T$35/Inputs!$H$35,0) | J21: =IF(AND(J$5>=Inputs!$W$35,J$5<Inputs!$I$35),Inputs!$T$35/Inputs!$H$35,0) | K21: =IF(AND(K$5>=Inputs!$W$35,K$5<Inputs!$I$35),Inputs!$T$35/Inputs!$H$35,0) | L21: =IF(AND(L$5>=Inputs!$W$35,L$5<Inputs!$I$35),Inputs!$T$35/Inputs!$H$35,0) | ... JT21: =IF(AND(JT$5>=Inputs!$W$35,JT$5<Inputs!$I$35),Inputs!$T$35/Inputs!$H$35,0)
B23: Bravo — BESS 75 MW / 300 MWh
B24: Operating flag | C24: 1/0 | E24: =IF(AND(E$5>=Inputs!$U$36,E$5<Inputs!$Z$36),1,0) | F24: =IF(AND(F$5>=Inputs!$U$36,F$5<Inputs!$Z$36),1,0) | G24: =IF(AND(G$5>=Inputs!$U$36,G$5<Inputs!$Z$36),1,0) | H24: =IF(AND(H$5>=Inputs!$U$36,H$5<Inputs!$Z$36),1,0) | I24: =IF(AND(I$5>=Inputs!$U$36,I$5<Inputs!$Z$36),1,0) | J24: =IF(AND(J$5>=Inputs!$U$36,J$5<Inputs!$Z$36),1,0) | K24: =IF(AND(K$5>=Inputs!$U$36,K$5<Inputs!$Z$36),1,0) | L24: =IF(AND(L$5>=Inputs!$U$36,L$5<Inputs!$Z$36),1,0) | ... JT24: =IF(AND(JT$5>=Inputs!$U$36,JT$5<Inputs!$Z$36),1,0)
B25: Operating year | C25: # | E25: =IF(E24=1,INT(((YEAR(E$5)-YEAR(Inputs!$U$36))*12+MONTH(E$5)-MONTH(Inputs!$U$36))/12),0) | F25: =IF(F24=1,INT(((YEAR(F$5)-YEAR(Inputs!$U$36))*12+MONTH(F$5)-MONTH(Inputs!$U$36))/12),0) | G25: =IF(G24=1,INT(((YEAR(G$5)-YEAR(Inputs!$U$36))*12+MONTH(G$5)-MONTH(Inputs!$U$36))/12),0) | H25: =IF(H24=1,INT(((YEAR(H$5)-YEAR(Inputs!$U$36))*12+MONTH(H$5)-MONTH(Inputs!$U$36))/12),0) | I25: =IF(I24=1,INT(((YEAR(I$5)-YEAR(Inputs!$U$36))*12+MONTH(I$5)-MONTH(Inputs!$U$36))/12),0) | J25: =IF(J24=1,INT(((YEAR(J$5)-YEAR(Inputs!$U$36))*12+MONTH(J$5)-MONTH(Inputs!$U$36))/12),0) | K25: =IF(K24=1,INT(((YEAR(K$5)-YEAR(Inputs!$U$36))*12+MONTH(K$5)-MONTH(Inputs!$U$36))/12),0) | L25: =IF(L24=1,INT(((YEAR(L$5)-YEAR(Inputs!$U$36))*12+MONTH(L$5)-MONTH(Inputs!$U$36))/12),0) | ... JT25: =IF(JT24=1,INT(((YEAR(JT$5)-YEAR(Inputs!$U$36))*12+MONTH(JT$5)-MONTH(Inputs!$U$36))/12),0)
B26: Accredited capacity (after degradation) | C26: MW | E26: =E24*Inputs!$D$36*Inputs!$J$36*(1-Inputs!$K$36)^E25 | F26: =F24*Inputs!$D$36*Inputs!$J$36*(1-Inputs!$K$36)^F25 | G26: =G24*Inputs!$D$36*Inputs!$J$36*(1-Inputs!$K$36)^G25 | H26: =H24*Inputs!$D$36*Inputs!$J$36*(1-Inputs!$K$36)^H25 | I26: =I24*Inputs!$D$36*Inputs!$J$36*(1-Inputs!$K$36)^I25 | J26: =J24*Inputs!$D$36*Inputs!$J$36*(1-Inputs!$K$36)^J25 | K26: =K24*Inputs!$D$36*Inputs!$J$36*(1-Inputs!$K$36)^K25 | L26: =L24*Inputs!$D$36*Inputs!$J$36*(1-Inputs!$K$36)^L25 | ... JT26: =JT24*Inputs!$D$36*Inputs!$J$36*(1-Inputs!$K$36)^JT25
B27: Capacity revenue | C27: $k | D27: =SUM(E27:JT27) | E27: =E26*E$8 | F27: =F26*F$8 | G27: =G26*G$8 | H27: =H26*H$8 | I27: =I26*I$8 | J27: =J26*J$8 | K27: =K26*K$8 | L27: =L26*L$8 | ... JT27: =JT26*JT$8
B28: Energy & ancillary margin | C28: $k | D28: =SUM(E28:JT28) | E28: =E26*Inputs!$M$36/12*E$9 | F28: =F26*Inputs!$M$36/12*F$9 | G28: =G26*Inputs!$M$36/12*G$9 | H28: =H26*Inputs!$M$36/12*H$9 | I28: =I26*Inputs!$M$36/12*I$9 | J28: =J26*Inputs!$M$36/12*J$9 | K28: =K26*Inputs!$M$36/12*K$9 | L28: =L26*Inputs!$M$36/12*L$9 | ... JT28: =JT26*Inputs!$M$36/12*JT$9
B29: Fixed O&M | C29: $k | D29: =SUM(E29:JT29) | E29: =E24*Inputs!$D$36*Inputs!$L$36/12*E$10*(1+OMAdj) | F29: =F24*Inputs!$D$36*Inputs!$L$36/12*F$10*(1+OMAdj) | G29: =G24*Inputs!$D$36*Inputs!$L$36/12*G$10*(1+OMAdj) | H29: =H24*Inputs!$D$36*Inputs!$L$36/12*H$10*(1+OMAdj) | I29: =I24*Inputs!$D$36*Inputs!$L$36/12*I$10*(1+OMAdj) | J29: =J24*Inputs!$D$36*Inputs!$L$36/12*J$10*(1+OMAdj) | K29: =K24*Inputs!$D$36*Inputs!$L$36/12*K$10*(1+OMAdj) | L29: =L24*Inputs!$D$36*Inputs!$L$36/12*L$10*(1+OMAdj) | ... JT29: =JT24*Inputs!$D$36*Inputs!$L$36/12*JT$10*(1+OMAdj)
B30: Insurance & property tax | C30: $k | D30: =SUM(E30:JT30) | E30: =E24*Inputs!$T$36*(Insurance+PropTax)/12 | F30: =F24*Inputs!$T$36*(Insurance+PropTax)/12 | G30: =G24*Inputs!$T$36*(Insurance+PropTax)/12 | H30: =H24*Inputs!$T$36*(Insurance+PropTax)/12 | I30: =I24*Inputs!$T$36*(Insurance+PropTax)/12 | J30: =J24*Inputs!$T$36*(Insurance+PropTax)/12 | K30: =K24*Inputs!$T$36*(Insurance+PropTax)/12 | L30: =L24*Inputs!$T$36*(Insurance+PropTax)/12 | ... JT30: =JT24*Inputs!$T$36*(Insurance+PropTax)/12
B31: Site lease | C31: $k | D31: =SUM(E31:JT31) | E31: =E24*Inputs!$N$36/12*E$10 | F31: =F24*Inputs!$N$36/12*F$10 | G31: =G24*Inputs!$N$36/12*G$10 | H31: =H24*Inputs!$N$36/12*H$10 | I31: =I24*Inputs!$N$36/12*I$10 | J31: =J24*Inputs!$N$36/12*J$10 | K31: =K24*Inputs!$N$36/12*K$10 | L31: =L24*Inputs!$N$36/12*L$10 | ... JT31: =JT24*Inputs!$N$36/12*JT$10
B32: Construction capex | C32: $k | D32: =SUM(E32:JT32) | E32: =IF(AND(E$5>=Inputs!$W$36,E$5<Inputs!$I$36),Inputs!$T$36/Inputs!$H$36,0) | F32: =IF(AND(F$5>=Inputs!$W$36,F$5<Inputs!$I$36),Inputs!$T$36/Inputs!$H$36,0) | G32: =IF(AND(G$5>=Inputs!$W$36,G$5<Inputs!$I$36),Inputs!$T$36/Inputs!$H$36,0) | H32: =IF(AND(H$5>=Inputs!$W$36,H$5<Inputs!$I$36),Inputs!$T$36/Inputs!$H$36,0) | I32: =IF(AND(I$5>=Inputs!$W$36,I$5<Inputs!$I$36),Inputs!$T$36/Inputs!$H$36,0) | J32: =IF(AND(J$5>=Inputs!$W$36,J$5<Inputs!$I$36),Inputs!$T$36/Inputs!$H$36,0) | K32: =IF(AND(K$5>=Inputs!$W$36,K$5<Inputs!$I$36),Inputs!$T$36/Inputs!$H$36,0) | L32: =IF(AND(L$5>=Inputs!$W$36,L$5<Inputs!$I$36),Inputs!$T$36/Inputs!$H$36,0) | ... JT32: =IF(AND(JT$5>=Inputs!$W$36,JT$5<Inputs!$I$36),Inputs!$T$36/Inputs!$H$36,0)
B34: Charlie — BESS 50 MW / 100 MWh
B35: Operating flag | C35: 1/0 | E35: =IF(AND(E$5>=Inputs!$U$37,E$5<Inputs!$Z$37),1,0) | F35: =IF(AND(F$5>=Inputs!$U$37,F$5<Inputs!$Z$37),1,0) | G35: =IF(AND(G$5>=Inputs!$U$37,G$5<Inputs!$Z$37),1,0) | H35: =IF(AND(H$5>=Inputs!$U$37,H$5<Inputs!$Z$37),1,0) | I35: =IF(AND(I$5>=Inputs!$U$37,I$5<Inputs!$Z$37),1,0) | J35: =IF(AND(J$5>=Inputs!$U$37,J$5<Inputs!$Z$37),1,0) | K35: =IF(AND(K$5>=Inputs!$U$37,K$5<Inputs!$Z$37),1,0) | L35: =IF(AND(L$5>=Inputs!$U$37,L$5<Inputs!$Z$37),1,0) | ... JT35: =IF(AND(JT$5>=Inputs!$U$37,JT$5<Inputs!$Z$37),1,0)
B36: Operating year | C36: # | E36: =IF(E35=1,INT(((YEAR(E$5)-YEAR(Inputs!$U$37))*12+MONTH(E$5)-MONTH(Inputs!$U$37))/12),0) | F36: =IF(F35=1,INT(((YEAR(F$5)-YEAR(Inputs!$U$37))*12+MONTH(F$5)-MONTH(Inputs!$U$37))/12),0) | G36: =IF(G35=1,INT(((YEAR(G$5)-YEAR(Inputs!$U$37))*12+MONTH(G$5)-MONTH(Inputs!$U$37))/12),0) | H36: =IF(H35=1,INT(((YEAR(H$5)-YEAR(Inputs!$U$37))*12+MONTH(H$5)-MONTH(Inputs!$U$37))/12),0) | I36: =IF(I35=1,INT(((YEAR(I$5)-YEAR(Inputs!$U$37))*12+MONTH(I$5)-MONTH(Inputs!$U$37))/12),0) | J36: =IF(J35=1,INT(((YEAR(J$5)-YEAR(Inputs!$U$37))*12+MONTH(J$5)-MONTH(Inputs!$U$37))/12),0) | K36: =IF(K35=1,INT(((YEAR(K$5)-YEAR(Inputs!$U$37))*12+MONTH(K$5)-MONTH(Inputs!$U$37))/12),0) | L36: =IF(L35=1,INT(((YEAR(L$5)-YEAR(Inputs!$U$37))*12+MONTH(L$5)-MONTH(Inputs!$U$37))/12),0) | ... JT36: =IF(JT35=1,INT(((YEAR(JT$5)-YEAR(Inputs!$U$37))*12+MONTH(JT$5)-MONTH(Inputs!$U$37))/12),0)
B37: Accredited capacity (after degradation) | C37: MW | E37: =E35*Inputs!$D$37*Inputs!$J$37*(1-Inputs!$K$37)^E36 | F37: =F35*Inputs!$D$37*Inputs!$J$37*(1-Inputs!$K$37)^F36 | G37: =G35*Inputs!$D$37*Inputs!$J$37*(1-Inputs!$K$37)^G36 | H37: =H35*Inputs!$D$37*Inputs!$J$37*(1-Inputs!$K$37)^H36 | I37: =I35*Inputs!$D$37*Inputs!$J$37*(1-Inputs!$K$37)^I36 | J37: =J35*Inputs!$D$37*Inputs!$J$37*(1-Inputs!$K$37)^J36 | K37: =K35*Inputs!$D$37*Inputs!$J$37*(1-Inputs!$K$37)^K36 | L37: =L35*Inputs!$D$37*Inputs!$J$37*(1-Inputs!$K$37)^L36 | ... JT37: =JT35*Inputs!$D$37*Inputs!$J$37*(1-Inputs!$K$37)^JT36
B38: Capacity revenue | C38: $k | D38: =SUM(E38:JT38) | E38: =E37*E$8 | F38: =F37*F$8 | G38: =G37*G$8 | H38: =H37*H$8 | I38: =I37*I$8 | J38: =J37*J$8 | K38: =K37*K$8 | L38: =L37*L$8 | ... JT38: =JT37*JT$8
B39: Energy & ancillary margin | C39: $k | D39: =SUM(E39:JT39) | E39: =E37*Inputs!$M$37/12*E$9 | F39: =F37*Inputs!$M$37/12*F$9 | G39: =G37*Inputs!$M$37/12*G$9 | H39: =H37*Inputs!$M$37/12*H$9 | I39: =I37*Inputs!$M$37/12*I$9 | J39: =J37*Inputs!$M$37/12*J$9 | K39: =K37*Inputs!$M$37/12*K$9 | L39: =L37*Inputs!$M$37/12*L$9 | ... JT39: =JT37*Inputs!$M$37/12*JT$9
B40: Fixed O&M | C40: $k | D40: =SUM(E40:JT40) | E40: =E35*Inputs!$D$37*Inputs!$L$37/12*E$10*(1+OMAdj) | F40: =F35*Inputs!$D$37*Inputs!$L$37/12*F$10*(1+OMAdj) | G40: =G35*Inputs!$D$37*Inputs!$L$37/12*G$10*(1+OMAdj) | H40: =H35*Inputs!$D$37*Inputs!$L$37/12*H$10*(1+OMAdj) | I40: =I35*Inputs!$D$37*Inputs!$L$37/12*I$10*(1+OMAdj) | J40: =J35*Inputs!$D$37*Inputs!$L$37/12*J$10*(1+OMAdj) | K40: =K35*Inputs!$D$37*Inputs!$L$37/12*K$10*(1+OMAdj) | L40: =L35*Inputs!$D$37*Inputs!$L$37/12*L$10*(1+OMAdj) | ... JT40: =JT35*Inputs!$D$37*Inputs!$L$37/12*JT$10*(1+OMAdj)
B41: Insurance & property tax | C41: $k | D41: =SUM(E41:JT41) | E41: =E35*Inputs!$T$37*(Insurance+PropTax)/12 | F41: =F35*Inputs!$T$37*(Insurance+PropTax)/12 | G41: =G35*Inputs!$T$37*(Insurance+PropTax)/12 | H41: =H35*Inputs!$T$37*(Insurance+PropTax)/12 | I41: =I35*Inputs!$T$37*(Insurance+PropTax)/12 | J41: =J35*Inputs!$T$37*(Insurance+PropTax)/12 | K41: =K35*Inputs!$T$37*(Insurance+PropTax)/12 | L41: =L35*Inputs!$T$37*(Insurance+PropTax)/12 | ... JT41: =JT35*Inputs!$T$37*(Insurance+PropTax)/12
B42: Site lease | C42: $k | D42: =SUM(E42:JT42) | E42: =E35*Inputs!$N$37/12*E$10 | F42: =F35*Inputs!$N$37/12*F$10 | G42: =G35*Inputs!$N$37/12*G$10 | H42: =H35*Inputs!$N$37/12*H$10 | I42: =I35*Inputs!$N$37/12*I$10 | J42: =J35*Inputs!$N$37/12*J$10 | K42: =K35*Inputs!$N$37/12*K$10 | L42: =L35*Inputs!$N$37/12*L$10 | ... JT42: =JT35*Inputs!$N$37/12*JT$10
B43: Construction capex | C43: $k | D43: =SUM(E43:JT43) | E43: =IF(AND(E$5>=Inputs!$W$37,E$5<Inputs!$I$37),Inputs!$T$37/Inputs!$H$37,0) | F43: =IF(AND(F$5>=Inputs!$W$37,F$5<Inputs!$I$37),Inputs!$T$37/Inputs!$H$37,0) | G43: =IF(AND(G$5>=Inputs!$W$37,G$5<Inputs!$I$37),Inputs!$T$37/Inputs!$H$37,0) | H43: =IF(AND(H$5>=Inputs!$W$37,H$5<Inputs!$I$37),Inputs!$T$37/Inputs!$H$37,0) | I43: =IF(AND(I$5>=Inputs!$W$37,I$5<Inputs!$I$37),Inputs!$T$37/Inputs!$H$37,0) | J43: =IF(AND(J$5>=Inputs!$W$37,J$5<Inputs!$I$37),Inputs!$T$37/Inputs!$H$37,0) | K43: =IF(AND(K$5>=Inputs!$W$37,K$5<Inputs!$I$37),Inputs!$T$37/Inputs!$H$37,0) | L43: =IF(AND(L$5>=Inputs!$W$37,L$5<Inputs!$I$37),Inputs!$T$37/Inputs!$H$37,0) | ... JT43: =IF(AND(JT$5>=Inputs!$W$37,JT$5<Inputs!$I$37),Inputs!$T$37/Inputs!$H$37,0)
B45: Delta — BESS 125 MW / 500 MWh
B46: Operating flag | C46: 1/0 | E46: =IF(AND(E$5>=Inputs!$U$38,E$5<Inputs!$Z$38),1,0) | F46: =IF(AND(F$5>=Inputs!$U$38,F$5<Inputs!$Z$38),1,0) | G46: =IF(AND(G$5>=Inputs!$U$38,G$5<Inputs!$Z$38),1,0) | H46: =IF(AND(H$5>=Inputs!$U$38,H$5<Inputs!$Z$38),1,0) | I46: =IF(AND(I$5>=Inputs!$U$38,I$5<Inputs!$Z$38),1,0) | J46: =IF(AND(J$5>=Inputs!$U$38,J$5<Inputs!$Z$38),1,0) | K46: =IF(AND(K$5>=Inputs!$U$38,K$5<Inputs!$Z$38),1,0) | L46: =IF(AND(L$5>=Inputs!$U$38,L$5<Inputs!$Z$38),1,0) | ... JT46: =IF(AND(JT$5>=Inputs!$U$38,JT$5<Inputs!$Z$38),1,0)
...

Sheet Annual
B2: Annual cash flows, debt & returns
B3: Monthly operations rolled up by calendar year; debt sized and repaid annually. $k.
B5: Year | C5: Scalar | D5: Total | E5: =YEAR(ModelStart) | F5: =E5+1 | G5: =F5+1 | H5: =G5+1 | I5: =H5+1 | J5: =I5+1 | K5: =J5+1 | L5: =K5+1 | M5: =L5+1 | ... AA5: =Z5+1
B7: Operations
B8: Capacity revenue | D8: =SUM(E8:AA8) | E8: =SUMIF(Monthly!$E$6:$JT$6,E$5,Monthly!$E$69:$JT$69) | F8: =SUMIF(Monthly!$E$6:$JT$6,F$5,Monthly!$E$69:$JT$69) | G8: =SUMIF(Monthly!$E$6:$JT$6,G$5,Monthly!$E$69:$JT$69) | H8: =SUMIF(Monthly!$E$6:$JT$6,H$5,Monthly!$E$69:$JT$69) | I8: =SUMIF(Monthly!$E$6:$JT$6,I$5,Monthly!$E$69:$JT$69) | J8: =SUMIF(Monthly!$E$6:$JT$6,J$5,Monthly!$E$69:$JT$69) | K8: =SUMIF(Monthly!$E$6:$JT$6,K$5,Monthly!$E$69:$JT$69) | L8: =SUMIF(Monthly!$E$6:$JT$6,L$5,Monthly!$E$69:$JT$69) | ... AA8: =SUMIF(Monthly!$E$6:$JT$6,AA$5,Monthly!$E$69:$JT$69)
B9: Energy & ancillary margin | D9: =SUM(E9:AA9) | E9: =SUMIF(Monthly!$E$6:$JT$6,E$5,Monthly!$E$70:$JT$70) | F9: =SUMIF(Monthly!$E$6:$JT$6,F$5,Monthly!$E$70:$JT$70) | G9: =SUMIF(Monthly!$E$6:$JT$6,G$5,Monthly!$E$70:$JT$70) | H9: =SUMIF(Monthly!$E$6:$JT$6,H$5,Monthly!$E$70:$JT$70) | I9: =SUMIF(Monthly!$E$6:$JT$6,I$5,Monthly!$E$70:$JT$70) | J9: =SUMIF(Monthly!$E$6:$JT$6,J$5,Monthly!$E$70:$JT$70) | K9: =SUMIF(Monthly!$E$6:$JT$6,K$5,Monthly!$E$70:$JT$70) | L9: =SUMIF(Monthly!$E$6:$JT$6,L$5,Monthly!$E$70:$JT$70) | ... AA9: =SUMIF(Monthly!$E$6:$JT$6,AA$5,Monthly!$E$70:$JT$70)
B10: Total revenue | D10: =SUM(E10:AA10) | E10: =E8+E9 | F10: =F8+F9 | G10: =G8+G9 | H10: =H8+H9 | I10: =I8+I9 | J10: =J8+J9 | K10: =K8+K9 | L10: =L8+L9 | ... AA10: =AA8+AA9
B11: Fixed O&M | D11: =SUM(E11:AA11) | E11: =SUMIF(Monthly!$E$6:$JT$6,E$5,Monthly!$E$72:$JT$72) | F11: =SUMIF(Monthly!$E$6:$JT$6,F$5,Monthly!$E$72:$JT$72) | G11: =SUMIF(Monthly!$E$6:$JT$6,G$5,Monthly!$E$72:$JT$72) | H11: =SUMIF(Monthly!$E$6:$JT$6,H$5,Monthly!$E$72:$JT$72) | I11: =SUMIF(Monthly!$E$6:$JT$6,I$5,Monthly!$E$72:$JT$72) | J11: =SUMIF(Monthly!$E$6:$JT$6,J$5,Monthly!$E$72:$JT$72) | K11: =SUMIF(Monthly!$E$6:$JT$6,K$5,Monthly!$E$72:$JT$72) | L11: =SUMIF(Monthly!$E$6:$JT$6,L$5,Monthly!$E$72:$JT$72) | ... AA11: =SUMIF(Monthly!$E$6:$JT$6,AA$5,Monthly!$E$72:$JT$72)
B12: Insurance & property tax | D12: =SUM(E12:AA12) | E12: =SUMIF(Monthly!$E$6:$JT$6,E$5,Monthly!$E$73:$JT$73) | F12: =SUMIF(Monthly!$E$6:$JT$6,F$5,Monthly!$E$73:$JT$73) | G12: =SUMIF(Monthly!$E$6:$JT$6,G$5,Monthly!$E$73:$JT$73) | H12: =SUMIF(Monthly!$E$6:$JT$6,H$5,Monthly!$E$73:$JT$73) | I12: =SUMIF(Monthly!$E$6:$JT$6,I$5,Monthly!$E$73:$JT$73) | J12: =SUMIF(Monthly!$E$6:$JT$6,J$5,Monthly!$E$73:$JT$73) | K12: =SUMIF(Monthly!$E$6:$JT$6,K$5,Monthly!$E$73:$JT$73) | L12: =SUMIF(Monthly!$E$6:$JT$6,L$5,Monthly!$E$73:$JT$73) | ... AA12: =SUMIF(Monthly!$E$6:$JT$6,AA$5,Monthly!$E$73:$JT$73)
B13: Site lease | D13: =SUM(E13:AA13) | E13: =SUMIF(Monthly!$E$6:$JT$6,E$5,Monthly!$E$74:$JT$74) | F13: =SUMIF(Monthly!$E$6:$JT$6,F$5,Monthly!$E$74:$JT$74) | G13: =SUMIF(Monthly!$E$6:$JT$6,G$5,Monthly!$E$74:$JT$74) | H13: =SUMIF(Monthly!$E$6:$JT$6,H$5,Monthly!$E$74:$JT$74) | I13: =SUMIF(Monthly!$E$6:$JT$6,I$5,Monthly!$E$74:$JT$74) | J13: =SUMIF(Monthly!$E$6:$JT$6,J$5,Monthly!$E$74:$JT$74) | K13: =SUMIF(Monthly!$E$6:$JT$6,K$5,Monthly!$E$74:$JT$74) | L13: =SUMIF(Monthly!$E$6:$JT$6,L$5,Monthly!$E$74:$JT$74) | ... AA13: =SUMIF(Monthly!$E$6:$JT$6,AA$5,Monthly!$E$74:$JT$74)
B14: Portfolio G&A | D14: =SUM(E14:AA14) | E14: =SUMIF(Monthly!$E$6:$JT$6,E$5,Monthly!$E$75:$JT$75) | F14: =SUMIF(Monthly!$E$6:$JT$6,F$5,Monthly!$E$75:$JT$75) | G14: =SUMIF(Monthly!$E$6:$JT$6,G$5,Monthly!$E$75:$JT$75) | H14: =SUMIF(Monthly!$E$6:$JT$6,H$5,Monthly!$E$75:$JT$75) | I14: =SUMIF(Monthly!$E$6:$JT$6,I$5,Monthly!$E$75:$JT$75) | J14: =SUMIF(Monthly!$E$6:$JT$6,J$5,Monthly!$E$75:$JT$75) | K14: =SUMIF(Monthly!$E$6:$JT$6,K$5,Monthly!$E$75:$JT$75) | L14: =SUMIF(Monthly!$E$6:$JT$6,L$5,Monthly!$E$75:$JT$75) | ... AA14: =SUMIF(Monthly!$E$6:$JT$6,AA$5,Monthly!$E$75:$JT$75)
B15: Total operating costs | D15: =SUM(E15:AA15) | E15: =SUM(E11:E14) | F15: =SUM(F11:F14) | G15: =SUM(G11:G14) | H15: =SUM(H11:H14) | I15: =SUM(I11:I14) | J15: =SUM(J11:J14) | K15: =SUM(K11:K14) | L15: =SUM(L11:L14) | ... AA15: =SUM(AA11:AA14)
B16: EBITDA (= pre-tax CFADS) | D16: =SUM(E16:AA16) | E16: =E10-E15 | F16: =F10-F15 | G16: =G10-G15 | H16: =H10-H15 | I16: =I10-I15 | J16: =J10-J15 | K16: =K10-K15 | L16: =L10-L15 | ... AA16: =AA10-AA15
B17: EBITDA margin | E17: =IF(E10=0,0,E16/E10) | F17: =IF(F10=0,0,F16/F10) | G17: =IF(G10=0,0,G16/G10) | H17: =IF(H10=0,0,H16/H10) | I17: =IF(I10=0,0,I16/I10) | J17: =IF(J10=0,0,J16/J10) | K17: =IF(K10=0,0,K16/K10) | L17: =IF(L10=0,0,L16/L10) | ... AA17: =IF(AA10=0,0,AA16/AA10)
B19: Capex, ITC & tax depreciation
B20: Construction capex | C20: =D20 | D20: =SUM(E20:AA20) | E20: =SUMIF(Monthly!$E$6:$JT$6,E$5,Monthly!$E$78:$JT$78) | F20: =SUMIF(Monthly!$E$6:$JT$6,F$5,Monthly!$E$78:$JT$78) | G20: =SUMIF(Monthly!$E$6:$JT$6,G$5,Monthly!$E$78:$JT$78) | H20: =SUMIF(Monthly!$E$6:$JT$6,H$5,Monthly!$E$78:$JT$78) | I20: =SUMIF(Monthly!$E$6:$JT$6,I$5,Monthly!$E$78:$JT$78) | J20: =SUMIF(Monthly!$E$6:$JT$6,J$5,Monthly!$E$78:$JT$78) | K20: =SUMIF(Monthly!$E$6:$JT$6,K$5,Monthly!$E$78:$JT$78) | L20: =SUMIF(Monthly!$E$6:$JT$6,L$5,Monthly!$E$78:$JT$78) | ... AA20: =SUMIF(Monthly!$E$6:$JT$6,AA$5,Monthly!$E$78:$JT$78)
B21: ITC cash received (transfer) | D21: =SUM(E21:AA21) | E21: =SUMPRODUCT((Inputs!$V$35:$V$39+1=E$5)*Inputs!$X$35:$X$39)*ITCTransfer | F21: =SUMPRODUCT((Inputs!$V$35:$V$39+1=F$5)*Inputs!$X$35:$X$39)*ITCTransfer | G21: =SUMPRODUCT((Inputs!$V$35:$V$39+1=G$5)*Inputs!$X$35:$X$39)*ITCTransfer | H21: =SUMPRODUCT((Inputs!$V$35:$V$39+1=H$5)*Inputs!$X$35:$X$39)*ITCTransfer | I21: =SUMPRODUCT((Inputs!$V$35:$V$39+1=I$5)*Inputs!$X$35:$X$39)*ITCTransfer | J21: =SUMPRODUCT((Inputs!$V$35:$V$39+1=J$5)*Inputs!$X$35:$X$39)*ITCTransfer | K21: =SUMPRODUCT((Inputs!$V$35:$V$39+1=K$5)*Inputs!$X$35:$X$39)*ITCTransfer | L21: =SUMPRODUCT((Inputs!$V$35:$V$39+1=L$5)*Inputs!$X$35:$X$39)*ITCTransfer | ... AA21: =SUMPRODUCT((Inputs!$V$35:$V$39+1=AA$5)*Inputs!$X$35:$X$39)*ITCTransfer
B22: Tax depreciation — Alpha | D22: =SUM(E22:AA22) | E22: =IF(OR((E$5-Inputs!$V$35+1)<1,(E$5-Inputs!$V$35+1)>16),0,IF(Inputs!$P$35=5,INDEX(MACRS_5,(E$5-Inputs!$V$35+1)),INDEX(MACRS_15,(E$5-Inputs!$V$35+1))))*Inputs!$Y$35 | F22: =IF(OR((F$5-Inputs!$V$35+1)<1,(F$5-Inputs!$V$35+1)>16),0,IF(Inputs!$P$35=5,INDEX(MACRS_5,(F$5-Inputs!$V$35+1)),INDEX(MACRS_15,(F$5-Inputs!$V$35+1))))*Inputs!$Y$35 | G22: =IF(OR((G$5-Inputs!$V$35+1)<1,(G$5-Inputs!$V$35+1)>16),0,IF(Inputs!$P$35=5,INDEX(MACRS_5,(G$5-Inputs!$V$35+1)),INDEX(MACRS_15,(G$5-Inputs!$V$35+1))))*Inputs!$Y$35 | H22: =IF(OR((H$5-Inputs!$V$35+1)<1,(H$5-Inputs!$V$35+1)>16),0,IF(Inputs!$P$35=5,INDEX(MACRS_5,(H$5-Inputs!$V$35+1)),INDEX(MACRS_15,(H$5-Inputs!$V$35+1))))*Inputs!$Y$35 | I22: =IF(OR((I$5-Inputs!$V$35+1)<1,(I$5-Inputs!$V$35+1)>16),0,IF(Inputs!$P$35=5,INDEX(MACRS_5,(I$5-Inputs!$V$35+1)),INDEX(MACRS_15,(I$5-Inputs!$V$35+1))))*Inputs!$Y$35 | J22: =IF(OR((J$5-Inputs!$V$35+1)<1,(J$5-Inputs!$V$35+1)>16),0,IF(Inputs!$P$35=5,INDEX(MACRS_5,(J$5-Inputs!$V$35+1)),INDEX(MACRS_15,(J$5-Inputs!$V$35+1))))*Inputs!$Y$35 | K22: =IF(OR((K$5-Inputs!$V$35+1)<1,(K$5-Inputs!$V$35+1)>16),0,IF(Inputs!$P$35=5,INDEX(MACRS_5,(K$5-Inputs!$V$35+1)),INDEX(MACRS_15,(K$5-Inputs!$V$35+1))))*Inputs!$Y$35 | L22: =IF(OR((L$5-Inputs!$V$35+1)<1,(L$5-Inputs!$V$35+1)>16),0,IF(Inputs!$P$35=5,INDEX(MACRS_5,(L$5-Inputs!$V$35+1)),INDEX(MACRS_15,(L$5-Inputs!$V$35+1))))*Inputs!$Y$35 | ... AA22: =IF(OR((AA$5-Inputs!$V$35+1)<1,(AA$5-Inputs!$V$35+1)>16),0,IF(Inputs!$P$35=5,INDEX(MACRS_5,(AA$5-Inputs!$V$35+1)),INDEX(MACRS_15,(AA$5-Inputs!$V$35+1))))*Inputs!$Y$35
B23: Tax depreciation — Bravo | D23: =SUM(E23:AA23) | E23: =IF(OR((E$5-Inputs!$V$36+1)<1,(E$5-Inputs!$V$36+1)>16),0,IF(Inputs!$P$36=5,INDEX(MACRS_5,(E$5-Inputs!$V$36+1)),INDEX(MACRS_15,(E$5-Inputs!$V$36+1))))*Inputs!$Y$36 | F23: =IF(OR((F$5-Inputs!$V$36+1)<1,(F$5-Inputs!$V$36+1)>16),0,IF(Inputs!$P$36=5,INDEX(MACRS_5,(F$5-Inputs!$V$36+1)),INDEX(MACRS_15,(F$5-Inputs!$V$36+1))))*Inputs!$Y$36 | G23: =IF(OR((G$5-Inputs!$V$36+1)<1,(G$5-Inputs!$V$36+1)>16),0,IF(Inputs!$P$36=5,INDEX(MACRS_5,(G$5-Inputs!$V$36+1)),INDEX(MACRS_15,(G$5-Inputs!$V$36+1))))*Inputs!$Y$36 | H23: =IF(OR((H$5-Inputs!$V$36+1)<1,(H$5-Inputs!$V$36+1)>16),0,IF(Inputs!$P$36=5,INDEX(MACRS_5,(H$5-Inputs!$V$36+1)),INDEX(MACRS_15,(H$5-Inputs!$V$36+1))))*Inputs!$Y$36 | I23: =IF(OR((I$5-Inputs!$V$36+1)<1,(I$5-Inputs!$V$36+1)>16),0,IF(Inputs!$P$36=5,INDEX(MACRS_5,(I$5-Inputs!$V$36+1)),INDEX(MACRS_15,(I$5-Inputs!$V$36+1))))*Inputs!$Y$36 | J23: =IF(OR((J$5-Inputs!$V$36+1)<1,(J$5-Inputs!$V$36+1)>16),0,IF(Inputs!$P$36=5,INDEX(MACRS_5,(J$5-Inputs!$V$36+1)),INDEX(MACRS_15,(J$5-Inputs!$V$36+1))))*Inputs!$Y$36 | K23: =IF(OR((K$5-Inputs!$V$36+1)<1,(K$5-Inputs!$V$36+1)>16),0,IF(Inputs!$P$36=5,INDEX(MACRS_5,(K$5-Inputs!$V$36+1)),INDEX(MACRS_15,(K$5-Inputs!$V$36+1))))*Inputs!$Y$36 | L23: =IF(OR((L$5-Inputs!$V$36+1)<1,(L$5-Inputs!$V$36+1)>16),0,IF(Inputs!$P$36=5,INDEX(MACRS_5,(L$5-Inputs!$V$36+1)),INDEX(MACRS_15,(L$5-Inputs!$V$36+1))))*Inputs!$Y$36 | ... AA23: =IF(OR((AA$5-Inputs!$V$36+1)<1,(AA$5-Inputs!$V$36+1)>16),0,IF(Inputs!$P$36=5,INDEX(MACRS_5,(AA$5-Inputs!$V$36+1)),INDEX(MACRS_15,(AA$5-Inputs!$V$36+1))))*Inputs!$Y$36
B24: Tax depreciation — Charlie | D24: =SUM(E24:AA24) | E24: =IF(OR((E$5-Inputs!$V$37+1)<1,(E$5-Inputs!$V$37+1)>16),0,IF(Inputs!$P$37=5,INDEX(MACRS_5,(E$5-Inputs!$V$37+1)),INDEX(MACRS_15,(E$5-Inputs!$V$37+1))))*Inputs!$Y$37 | F24: =IF(OR((F$5-Inputs!$V$37+1)<1,(F$5-Inputs!$V$37+1)>16),0,IF(Inputs!$P$37=5,INDEX(MACRS_5,(F$5-Inputs!$V$37+1)),INDEX(MACRS_15,(F$5-Inputs!$V$37+1))))*Inputs!$Y$37 | G24: =IF(OR((G$5-Inputs!$V$37+1)<1,(G$5-Inputs!$V$37+1)>16),0,IF(Inputs!$P$37=5,INDEX(MACRS_5,(G$5-Inputs!$V$37+1)),INDEX(MACRS_15,(G$5-Inputs!$V$37+1))))*Inputs!$Y$37 | H24: =IF(OR((H$5-Inputs!$V$37+1)<1,(H$5-Inputs!$V$37+1)>16),0,IF(Inputs!$P$37=5,INDEX(MACRS_5,(H$5-Inputs!$V$37+1)),INDEX(MACRS_15,(H$5-Inputs!$V$37+1))))*Inputs!$Y$37 | I24: =IF(OR((I$5-Inputs!$V$37+1)<1,(I$5-Inputs!$V$37+1)>16),0,IF(Inputs!$P$37=5,INDEX(MACRS_5,(I$5-Inputs!$V$37+1)),INDEX(MACRS_15,(I$5-Inputs!$V$37+1))))*Inputs!$Y$37 | J24: =IF(OR((J$5-Inputs!$V$37+1)<1,(J$5-Inputs!$V$37+1)>16),0,IF(Inputs!$P$37=5,INDEX(MACRS_5,(J$5-Inputs!$V$37+1)),INDEX(MACRS_15,(J$5-Inputs!$V$37+1))))*Inputs!$Y$37 | K24: =IF(OR((K$5-Inputs!$V$37+1)<1,(K$5-Inputs!$V$37+1)>16),0,IF(Inputs!$P$37=5,INDEX(MACRS_5,(K$5-Inputs!$V$37+1)),INDEX(MACRS_15,(K$5-Inputs!$V$37+1))))*Inputs!$Y$37 | L24: =IF(OR((L$5-Inputs!$V$37+1)<1,(L$5-Inputs!$V$37+1)>16),0,IF(Inputs!$P$37=5,INDEX(MACRS_5,(L$5-Inputs!$V$37+1)),INDEX(MACRS_15,(L$5-Inputs!$V$37+1))))*Inputs!$Y$37 | ... AA24: =IF(OR((AA$5-Inputs!$V$37+1)<1,(AA$5-Inputs!$V$37+1)>16),0,IF(Inputs!$P$37=5,INDEX(MACRS_5,(AA$5-Inputs!$V$37+1)),INDEX(MACRS_15,(AA$5-Inputs!$V$37+1))))*Inputs!$Y$37
B25: Tax depreciation — Delta | D25: =SUM(E25:AA25) | E25: =IF(OR((E$5-Inputs!$V$38+1)<1,(E$5-Inputs!$V$38+1)>16),0,IF(Inputs!$P$38=5,INDEX(MACRS_5,(E$5-Inputs!$V$38+1)),INDEX(MACRS_15,(E$5-Inputs!$V$38+1))))*Inputs!$Y$38 | F25: =IF(OR((F$5-Inputs!$V$38+1)<1,(F$5-Inputs!$V$38+1)>16),0,IF(Inputs!$P$38=5,INDEX(MACRS_5,(F$5-Inputs!$V$38+1)),INDEX(MACRS_15,(F$5-Inputs!$V$38+1))))*Inputs!$Y$38 | G25: =IF(OR((G$5-Inputs!$V$38+1)<1,(G$5-Inputs!$V$38+1)>16),0,IF(Inputs!$P$38=5,INDEX(MACRS_5,(G$5-Inputs!$V$38+1)),INDEX(MACRS_15,(G$5-Inputs!$V$38+1))))*Inputs!$Y$38 | H25: =IF(OR((H$5-Inputs!$V$38+1)<1,(H$5-Inputs!$V$38+1)>16),0,IF(Inputs!$P$38=5,INDEX(MACRS_5,(H$5-Inputs!$V$38+1)),INDEX(MACRS_15,(H$5-Inputs!$V$38+1))))*Inputs!$Y$38 | I25: =IF(OR((I$5-Inputs!$V$38+1)<1,(I$5-Inputs!$V$38+1)>16),0,IF(Inputs!$P$38=5,INDEX(MACRS_5,(I$5-Inputs!$V$38+1)),INDEX(MACRS_15,(I$5-Inputs!$V$38+1))))*Inputs!$Y$38 | J25: =IF(OR((J$5-Inputs!$V$38+1)<1,(J$5-Inputs!$V$38+1)>16),0,IF(Inputs!$P$38=5,INDEX(MACRS_5,(J$5-Inputs!$V$38+1)),INDEX(MACRS_15,(J$5-Inputs!$V$38+1))))*Inputs!$Y$38 | K25: =IF(OR((K$5-Inputs!$V$38+1)<1,(K$5-Inputs!$V$38+1)>16),0,IF(Inputs!$P$38=5,INDEX(MACRS_5,(K$5-Inputs!$V$38+1)),INDEX(MACRS_15,(K$5-Inputs!$V$38+1))))*Inputs!$Y$38 | L25: =IF(OR((L$5-Inputs!$V$38+1)<1,(L$5-Inputs!$V$38+1)>16),0,IF(Inputs!$P$38=5,INDEX(MACRS_5,(L$5-Inputs!$V$38+1)),INDEX(MACRS_15,(L$5-Inputs!$V$38+1))))*Inputs!$Y$38 | ... AA25: =IF(OR((AA$5-Inputs!$V$38+1)<1,(AA$5-Inputs!$V$38+1)>16),0,IF(Inputs!$P$38=5,INDEX(MACRS_5,(AA$5-Inputs!$V$38+1)),INDEX(MACRS_15,(AA$5-Inputs!$V$38+1))))*Inputs!$Y$38
B26: Tax depreciation — Echo | D26: =SUM(E26:AA26) | E26: =IF(OR((E$5-Inputs!$V$39+1)<1,(E$5-Inputs!$V$39+1)>16),0,IF(Inputs!$P$39=5,INDEX(MACRS_5,(E$5-Inputs!$V$39+1)),INDEX(MACRS_15,(E$5-Inputs!$V$39+1))))*Inputs!$Y$39 | F26: =IF(OR((F$5-Inputs!$V$39+1)<1,(F$5-Inputs!$V$39+1)>16),0,IF(Inputs!$P$39=5,INDEX(MACRS_5,(F$5-Inputs!$V$39+1)),INDEX(MACRS_15,(F$5-Inputs!$V$39+1))))*Inputs!$Y$39 | G26: =IF(OR((G$5-Inputs!$V$39+1)<1,(G$5-Inputs!$V$39+1)>16),0,IF(Inputs!$P$39=5,INDEX(MACRS_5,(G$5-Inputs!$V$39+1)),INDEX(MACRS_15,(G$5-Inputs!$V$39+1))))*Inputs!$Y$39 | H26: =IF(OR((H$5-Inputs!$V$39+1)<1,(H$5-Inputs!$V$39+1)>16),0,IF(Inputs!$P$39=5,INDEX(MACRS_5,(H$5-Inputs!$V$39+1)),INDEX(MACRS_15,(H$5-Inputs!$V$39+1))))*Inputs!$Y$39 | I26: =IF(OR((I$5-Inputs!$V$39+1)<1,(I$5-Inputs!$V$39+1)>16),0,IF(Inputs!$P$39=5,INDEX(MACRS_5,(I$5-Inputs!$V$39+1)),INDEX(MACRS_15,(I$5-Inputs!$V$39+1))))*Inputs!$Y$39 | J26: =IF(OR((J$5-Inputs!$V$39+1)<1,(J$5-Inputs!$V$39+1)>16),0,IF(Inputs!$P$39=5,INDEX(MACRS_5,(J$5-Inputs!$V$39+1)),INDEX(MACRS_15,(J$5-Inputs!$V$39+1))))*Inputs!$Y$39 | K26: =IF(OR((K$5-Inputs!$V$39+1)<1,(K$5-Inputs!$V$39+1)>16),0,IF(Inputs!$P$39=5,INDEX(MACRS_5,(K$5-Inputs!$V$39+1)),INDEX(MACRS_15,(K$5-Inputs!$V$39+1))))*Inputs!$Y$39 | L26: =IF(OR((L$5-Inputs!$V$39+1)<1,(L$5-Inputs!$V$39+1)>16),0,IF(Inputs!$P$39=5,INDEX(MACRS_5,(L$5-Inputs!$V$39+1)),INDEX(MACRS_15,(L$5-Inputs!$V$39+1))))*Inputs!$Y$39 | ... AA26: =IF(OR((AA$5-Inputs!$V$39+1)<1,(AA$5-Inputs!$V$39+1)>16),0,IF(Inputs!$P$39=5,INDEX(MACRS_5,(AA$5-Inputs!$V$39+1)),INDEX(MACRS_15,(AA$5-Inputs!$V$39+1))))*Inputs!$Y$39
B27: Total tax depreciation | D27: =SUM(E27:AA27) | E27: =SUM(E22:E26) | F27: =SUM(F22:F26) | G27: =SUM(G22:G26) | H27: =SUM(H22:H26) | I27: =SUM(I22:I26) | J27: =SUM(J22:J26) | K27: =SUM(K22:K26) | L27: =SUM(L22:L26) | ... AA27: =SUM(AA22:AA26)
B29: Debt sizing (sculpted to target DSCR, drawn at term conversion)
B30: Term conversion year (latest live COD) | C30: =MAX(Inputs!$V$35:$V$39)
B31: Senior rate (live) | C31: =SrRateBase+RateAdj/10000
B32: Mezzanine rate (live) | C32: =MzRateBase+RateAdj/10000
B34: Years from conversion | E34: =E$5-ConvYear | F34: =F$5-ConvYear | G34: =G$5-ConvYear | H34: =H$5-ConvYear | I34: =I$5-ConvYear | J34: =J$5-ConvYear | K34: =K$5-ConvYear | L34: =L$5-ConvYear | ... AA34: =AA$5-ConvYear
B35: Debt service period flag | E35: =IF(AND(E34>=1,E34<=Tenor),1,0) | F35: =IF(AND(F34>=1,F34<=Tenor),1,0) | G35: =IF(AND(G34>=1,G34<=Tenor),1,0) | H35: =IF(AND(H34>=1,H34<=Tenor),1,0) | I35: =IF(AND(I34>=1,I34<=Tenor),1,0) | J35: =IF(AND(J34>=1,J34<=Tenor),1,0) | K35: =IF(AND(K34>=1,K34<=Tenor),1,0) | L35: =IF(AND(L34>=1,L34<=Tenor),1,0) | ... AA35: =IF(AND(AA34>=1,AA34<=Tenor),1,0)
B36: CFADS available for debt service | D36: =SUM(E36:AA36) | E36: =E35*E16 | F36: =F35*F16 | G36: =G35*G16 | H36: =H35*H16 | I36: =I35*I16 | J36: =J35*J16 | K36: =K35*K16 | L36: =L35*L16 | ... AA36: =AA35*AA16
B38: Senior debt
B39: Debt service at target DSCR (uncapped) | D39: =SUM(E39:AA39) | E39: =E36/SrDSCR | F39: =F36/SrDSCR | G39: =G36/SrDSCR | H39: =H36/SrDSCR | I39: =I36/SrDSCR | J39: =J36/SrDSCR | K39: =K36/SrDSCR | L39: =L36/SrDSCR | ... AA39: =AA36/SrDSCR
B40: Discount factor at senior rate | E40: =IF(E35=1,1/(1+SrRate)^E34,0) | F40: =IF(F35=1,1/(1+SrRate)^F34,0) | G40: =IF(G35=1,1/(1+SrRate)^G34,0) | H40: =IF(H35=1,1/(1+SrRate)^H34,0) | I40: =IF(I35=1,1/(1+SrRate)^I34,0) | J40: =IF(J35=1,1/(1+SrRate)^J34,0) | K40: =IF(K35=1,1/(1+SrRate)^K34,0) | L40: =IF(L35=1,1/(1+SrRate)^L34,0) | ... AA40: =IF(AA35=1,1/(1+SrRate)^AA34,0)
B41: Debt capacity from sculpting (PV of DS) | C41: =SUMPRODUCT(E39:AA39,E40:AA40)
B42: Gearing cap (senior max gearing × capex) | C42: =SrMaxGear*TotalCapex
B43: Senior debt amount | C43: =MIN(C41,C42) | D43: =IF(C42<C41,"gearing-capped","DSCR-sized")
B44: Senior debt service | D44: =SUM(E44:AA44) | E44: =IF(C41=0,0,E39*SrAmt/$C$41) | F44: =IF(C41=0,0,F39*SrAmt/$C$41) | G44: =IF(C41=0,0,G39*SrAmt/$C$41) | H44: =IF(C41=0,0,H39*SrAmt/$C$41) | I44: =IF(C41=0,0,I39*SrAmt/$C$41) | J44: =IF(C41=0,0,J39*SrAmt/$C$41) | K44: =IF(C41=0,0,K39*SrAmt/$C$41) | L44: =IF(C41=0,0,L39*SrAmt/$C$41) | M44: =IF(C41=0,0,M39*SrAmt/$C$41) | N44: =IF(C41=0,0,N39*SrAmt/$C$41) | O44: =IF(C41=0,0,O39*SrAmt/$C$41) | P44: =IF(C41=0,0,P39*SrAmt/$C$41) | Q44: =IF(C41=0,0,Q39*SrAmt/$C$41) | R44: =IF(C41=0,0,R39*SrAmt/$C$41) | S44: =IF(C41=0,0,S39*SrAmt/$C$41) | T44: =IF(C41=0,0,T39*SrAmt/$C$41) | U44: =IF(C41=0,0,U39*SrAmt/$C$41) | V44: =IF(C41=0,0,V39*SrAmt/$C$41) | W44: =IF(C41=0,0,W39*SrAmt/$C$41) | X44: =IF(C41=0,0,X39*SrAmt/$C$41) | Y44: =IF(C41=0,0,Y39*SrAmt/$C$41) | Z44: =IF(C41=0,0,Z39*SrAmt/$C$41) | AA44: =IF(C41=0,0,AA39*SrAmt/$C$41)
B45: Opening balance | E45: =0 | F45: =E49 | G45: =F49 | H45: =G49 | I45: =H49 | J45: =I49 | K45: =J49 | L45: =K49 | M45: =L49 | ... AA45: =Z49
B46: Drawdown | D46: =SUM(E46:AA46) | E46: =IF(E$5=ConvYear,SrAmt,0) | F46: =IF(F$5=ConvYear,SrAmt,0) | G46: =IF(G$5=ConvYear,SrAmt,0) | H46: =IF(H$5=ConvYear,SrAmt,0) | I46: =IF(I$5=ConvYear,SrAmt,0) | J46: =IF(J$5=ConvYear,SrAmt,0) | K46: =IF(K$5=ConvYear,SrAmt,0) | L46: =IF(L$5=ConvYear,SrAmt,0) | ... AA46: =IF(AA$5=ConvYear,SrAmt,0)
B47: Interest | D47: =SUM(E47:AA47) | E47: =E45*SrRate | F47: =F45*SrRate | G47: =G45*SrRate | H47: =H45*SrRate | I47: =I45*SrRate | J47: =J45*SrRate | K47: =K45*SrRate | L47: =L45*SrRate | ... AA47: =AA45*SrRate
...

Sheet Assumption Log
B2: Assumption Log
B3: Every input, who owns it, the basis used, and what to validate it against. Values link live to Inputs.
B5: ID | C5: Category | D5: Assumption | E5: Value | F5: Unit | G5: Owner (source team) | H5: Basis / rationale | I5: Validate against | J5: Status
B6: A-01 | C6: Revenue | D6: Capacity price (2027 $) | E6: =CapPrice | F6: $/kW-month | G6: Commercial | H6: Illustrative 2027 capacity price, set near the level that clears the target return | I6: Recent ISO/RTO capacity auction results (e.g. PJM BRA, NYISO ICAP, ISO-NE FCA) and bilateral RA contract quotes | J6: Illustrative — to validate
B7: A-02 | C7: Revenue | D7: Capacity price & margin escalation | E7: =PriceEsc | F7: % / yr | G7: Commercial | H7: Roughly inflation-linked | I7: Contract escalators in RA/capacity agreements; forward curves | J7: Illustrative — to validate
B8: A-03 | C8: Opex | D8: O&M, lease & G&A escalation | E8: =OMEsc | F8: % / yr | G8: Asset Management | H8: Slightly above CPI for labor-heavy O&M | I8: O&M / LTSA contract escalators | J8: Illustrative — to validate
B9: A-04 | C9: Capex | D9: Owner's costs & contingency | E9: =Contingency | F9: % of EPC | G9: Engineering / EPC | H9: Owner's costs, interconnection true-ups and contingency | I9: EPC bid spread; interconnection study cost estimates | J9: Illustrative — to validate
B10: A-05 | C10: Opex | D10: Insurance | E10: =Insurance | F10: % capex / yr | G10: Risk / Insurance | H10: Typical % of replacement cost for BESS | I10: Broker indications | J10: Illustrative — to validate
B11: A-06 | C11: Opex | D11: Property tax | E11: =PropTax | F11: % capex / yr | G11: Tax | H11: Varies by jurisdiction and abatements | I11: County assessor / PILOT agreements | J11: Illustrative — to validate
B12: A-07 | C12: Opex | D12: Portfolio G&A and asset management | E12: =GACost | F12: $k / yr | G12: Finance | H12: Portfolio-level asset management and corporate overhead | I12: Internal budget | J12: Illustrative — to validate
B13: A-08 | C13: Tax | D13: Blended income tax rate | E13: =TaxRate | F13: % | G13: Tax | H13: 21% federal + ~5% blended state | I13: Tax department; state apportionment | J13: Illustrative — to validate
B14: A-09 | C14: Tax | D14: Investment tax credit (storage only) | E14: =ITCRate | F14: % eligible capex | G14: Tax | H14: 30% base credit assuming prevailing wage & apprenticeship; no adders | I14: Current §48E rules incl. any phase-down and FEOC restrictions | J14: Illustrative — to validate
B15: A-10 | C15: Tax | D15: ITC transfer price | E15: =ITCTransfer | F15: $ per $1 credit | G15: Tax / Treasury | H15: Credit sold to a third party under transferability | I15: Recent transfer market quotes from advisors / brokers | J15: Illustrative — to validate
B16: A-11 | C16: Tax | D16: Depreciable basis reduction | E16: =ITCBasisRed | F16: % of ITC | G16: Tax | H16: Basis reduced by 50% of ITC | I16: Tax counsel | J16: Illustrative — to validate
B17: A-12 | C17: Financing | D17: Senior debt interest rate | E17: =SrRateBase | F17: % / yr | G17: Treasury / Capital Markets | H17: Base rate + margin for contracted storage debt | I17: Lender term sheets; SOFR swap curve | J17: Illustrative — to validate
B18: A-13 | C18: Financing | D18: Senior target DSCR | E18: =SrDSCR | F18: x | G18: Treasury / Capital Markets | H18: Contracted capacity revenue supports a mid-1.3x DSCR | I18: Lender term sheets / rating agency criteria | J18: Illustrative — to validate
B19: A-14 | C19: Financing | D19: Senior max gearing | E19: =SrMaxGear | F19: % of capex | G19: Treasury / Capital Markets | H19: Typical leverage ceiling | I19: Lender term sheets | J19: Illustrative — to validate
B20: A-15 | C20: Financing | D20: Senior upfront fee | E20: =SrFee | F20: % of amount | G20: Treasury / Capital Markets | H20: Arrangement fee | I20: Lender term sheets | J20: Illustrative — to validate
B21: A-16 | C21: Financing | D21: Mezzanine interest rate | E21: =MzRateBase | F21: % / yr | G21: Treasury / Capital Markets | H21: Subordinated / holdco debt pricing | I21: Mezz lender indications | J21: Illustrative — to validate
B22: A-17 | C22: Financing | D22: Combined (senior + mezz) target DSCR | E22: =CombDSCR | F22: x | G22: Treasury / Capital Markets | H22: Mezz sized to the gap between senior and combined DSCR | I22: Mezz lender indications | J22: Illustrative — to validate
B23: A-18 | C23: Financing | D23: Total max gearing | E23: =TotMaxGear | F23: % of capex | G23: Treasury / Capital Markets | H23: Total leverage ceiling | I23: Lender term sheets | J23: Illustrative — to validate
B24: A-19 | C24: Financing | D24: Mezzanine upfront fee | E24: =MzFee | F24: % of amount | G24: Treasury / Capital Markets | H24: Arrangement fee | I24: Mezz lender indications | J24: Illustrative — to validate
B25: A-20 | C25: Financing | D25: Debt tenor (both tranches) | E25: =Tenor | F25: years | G25: Treasury / Capital Markets | H25: Shorter than 20-year asset life | I25: Lender term sheets; contract tenor | J25: Illustrative — to validate
B26: A-21 | C26: Returns | D26: Cost of equity / target equity IRR | E26: =CostEquity | F26: % | G26: Investment Committee | H26: Sponsor hurdle for contracted storage | I26: IC hurdle rates; comparable transactions | J26: Illustrative — to validate
B27: A-22 | C27: Capex | D27: Alpha — EPC unit cost | E27: =Inputs!F35 | F27: $/kWh | G27: Engineering / EPC | H27: All-in EPC for 4h/2h storage and recip engine backup generation | I27: EPC bids; NREL Annual Technology Baseline; Lazard LCOE+/LCOS | J27: Illustrative — to validate
B28: A-23 | C28: Capex | D28: Bravo — EPC unit cost | E28: =Inputs!F36 | F28: $/kWh | G28: Engineering / EPC | H28: All-in EPC for 4h/2h storage and recip engine backup generation | I28: EPC bids; NREL Annual Technology Baseline; Lazard LCOE+/LCOS | J28: Illustrative — to validate
B29: A-24 | C29: Capex | D29: Charlie — EPC unit cost | E29: =Inputs!F37 | F29: $/kWh | G29: Engineering / EPC | H29: All-in EPC for 4h/2h storage and recip engine backup generation | I29: EPC bids; NREL Annual Technology Baseline; Lazard LCOE+/LCOS | J29: Illustrative — to validate
B30: A-25 | C30: Capex | D30: Delta — EPC unit cost | E30: =Inputs!F38 | F30: $/kWh | G30: Engineering / EPC | H30: All-in EPC for 4h/2h storage and recip engine backup generation | I30: EPC bids; NREL Annual Technology Baseline; Lazard LCOE+/LCOS | J30: Illustrative — to validate
B31: A-26 | C31: Capex | D31: Echo — EPC unit cost | E31: =Inputs!F39 | F31: $/kW | G31: Engineering / EPC | H31: All-in EPC for 4h/2h storage and recip engine backup generation | I31: EPC bids; NREL Annual Technology Baseline; Lazard LCOE+/LCOS | J31: Illustrative — to validate
B32: A-27 | C32: Timing | D32: Alpha — COD (base) | E32: =Inputs!I35 | F32: date | G32: Development / Construction | H32: Staggered CODs Dec-27 to Jul-28 | I32: Interconnection agreements; EPC schedule | J32: Illustrative — to validate
B33: A-28 | C33: Timing | D33: Bravo — COD (base) | E33: =Inputs!I36 | F33: date | G33: Development / Construction | H33: Staggered CODs Dec-27 to Jul-28 | I33: Interconnection agreements; EPC schedule | J33: Illustrative — to validate
B34: A-29 | C34: Timing | D34: Charlie — COD (base) | E34: =Inputs!I37 | F34: date | G34: Development / Construction | H34: Staggered CODs Dec-27 to Jul-28 | I34: Interconnection agreements; EPC schedule | J34: Illustrative — to validate
B35: A-30 | C35: Timing | D35: Delta — COD (base) | E35: =Inputs!I38 | F35: date | G35: Development / Construction | H35: Staggered CODs Dec-27 to Jul-28 | I35: Interconnection agreements; EPC schedule | J35: Illustrative — to validate
B36: A-31 | C36: Timing | D36: Echo — COD (base) | E36: =Inputs!I39 | F36: date | G36: Development / Construction | H36: Staggered CODs Dec-27 to Jul-28 | I36: Interconnection agreements; EPC schedule | J36: Illustrative — to validate
B37: A-32 | C37: Revenue | D37: Alpha — Capacity accreditation | E37: =Inputs!J35 | F37: % | G37: Commercial | H37: Effective load carrying capability by duration | I37: ISO accreditation (ELCC) tables | J37: Illustrative — to validate
B38: A-33 | C38: Revenue | D38: Bravo — Capacity accreditation | E38: =Inputs!J36 | F38: % | G38: Commercial | H38: Effective load carrying capability by duration | I38: ISO accreditation (ELCC) tables | J38: Illustrative — to validate
B39: A-34 | C39: Revenue | D39: Charlie — Capacity accreditation | E39: =Inputs!J37 | F39: % | G39: Commercial | H39: Effective load carrying capability by duration | I39: ISO accreditation (ELCC) tables | J39: Illustrative — to validate
B40: A-35 | C40: Revenue | D40: Delta — Capacity accreditation | E40: =Inputs!J38 | F40: % | G40: Commercial | H40: Effective load carrying capability by duration | I40: ISO accreditation (ELCC) tables | J40: Illustrative — to validate
B41: A-36 | C41: Revenue | D41: Echo — Capacity accreditation | E41: =Inputs!J39 | F41: % | G41: Commercial | H41: Effective load carrying capability by duration | I41: ISO accreditation (ELCC) tables | J41: Illustrative — to validate
